Workbook

Sheet avance real 
A1: PRESUPUESTO OBRAS CIVILES
A2: Licitación: CONSERVACIÓN ESCUELA JUAN SANDOVAL CARRASCO | E2: Fecha: 03-03-2025 | G2: % Avance | H2: =J152/F152 -> 0.066699314
A3: Ubicación: SANTA ELENA N°385, COQUIMBO | E3: Versión:
A4: Ítem | B4: Descripción | C4: Unidad | D4: Cantidad | E4: P. Unitario ($) | F4: P. Total ($) | G4: Cant avance | H4: unidad | I4: avance % | J4: monto avance
A5: 0 | B5: GENERALIDADES
A6: 1 | B6: OBRAS PREVIAS
A7: 1.1 | B7: Letrero indicativo de la obra | C7: Un | D7: 1 | E7: 1450000 | F7: =D7*E7 -> 1450000 | G7: 1 | H7: unidad | I7: =G7*100%/D7 -> 1 | J7: =F7*I7 -> 1450000
A8: 1.2 | B8: Cierres Provisorios | C8: M. Lineal | D8: 60 | E8: 38500 | F8: =D8*E8 -> 2310000 | G8: 30 | H8: m lineal | I8: =G8*100%/D8 -> 0.5 | J8: =F8*I8 -> 1155000
A9: 1.3 | B9: Intalación de faena
A10: 1.3.1 | B10: Oficina Jefatura | C10: INCLUIDO EN GASTOS GENERALES | G10: INCLUIDO EN GASTOS GENERALES
A11: 1.3.2 | B11: Bodegas | C11: INCLUIDO EN GASTOS GENERALES | G11: INCLUIDO EN GASTOS GENERALES
A12: 1.3.3 | B12: Comedor | C12: INCLUIDO EN GASTOS GENERALES | G12: INCLUIDO EN GASTOS GENERALES
A13: 1.3.4 | B13: Servicios Higienicos | C13: INCLUIDO EN GASTOS GENERALES | G13: INCLUIDO EN GASTOS GENERALES
A14: 1.3.5 | B14: Camarines | C14: INCLUIDO EN GASTOS GENERALES | G14: INCLUIDO EN GASTOS GENERALES
C15: SUBTOTAL
A16: 2 | B16: MEJORAMIENTO
A17: 2.1 | B17: Mejoramiento Complejo de Cubierta
A18: 2.1.1 | B18: Retiro de cubierta existente
A19: 2.1.1.1 | B19: Retiro de cubierta existente zinc | C19: m² | D19: 609.01 | E19: =+P.U!F28 -> 7246 | F19: =ROUND(D19*E19,0) -> 4412886 | G19: 360 | H19: m2 | I19: =G19*100%/D19 -> 0.5911233 | J19: =I19*F19 -> 2608559.7
A20: 2.1.1.2 | B20: Retiro, traslado y dispoción de cubierta de asbesto cemento | C20: m² | D20: 1271.71 | E20: =+P.U!F75 -> 24172 | F20: =ROUND(D20*E20,0) -> 30739774 | I20: =G20*100%/D20 -> 0 | J20: =I20*F20 -> 0
A21: 2.1.2 | B21: Lana de vidrio 91mm R100/213 (Para cubierta PV4) | C21: m² | D21: 1880.72 | E21: =P.U!F114 -> 3885 | F21: =ROUND(D21*E21,0) -> 7306597 | I21: =G21*100%/D21 -> 0 | J21: =I21*F21 -> 0
A22: 2.1.3 | B22: Membrana Hidrofuga Tyvek (Para cubierta PV4) | C22: m² | D22: 1880.72 | E22: =P.U!F159 -> 2611 | F22: =ROUND(D22*E22,0) -> 4910560 | I22: =G22*100%/D22 -> 0 | J22: =I22*F22 -> 0
A23: 2.1.4 | B23: Placa OSB (Para cubierta PV4) | C23: m² | D23: 1880.72 | E23: =P.U!F203 -> 8920 | F23: =ROUND(D23*E23,0) -> 16776022 | G23: 360 | H23: m2 | I23: =G23*100%/D23 -> 0.19141605 | J23: =I23*F23 -> 3211199.9
A24: 2.1.5 | B24: Cubierta PV4 | C24: m² | D24: 1880.72 | E24: =P.U!F248 -> 18515 | F24: =ROUND(D24*E24,0) -> 34821531 | I24: =G24*100%/D24 -> 0 | J24: =I24*F24 -> 0
A25: 2.1.6 | B25: Hojalatería Zincalum liso 0.5mm - CABALLETE | C25: m | D25: 244 | E25: =+P.U!F291 -> 10463 | F25: =ROUND(D25*E25,0) -> 2552972 | G25: =28+15 -> 43 | I25: =G25*100%/D25 -> 0.17622951 | J25: =I25*F25 -> 449909
A26: 2.1.7 | B26: Hojalatería Zincalum liso 0.5mm - CANALETA | C26: m | D26: 175 | E26: =+P.U!F335 -> 27608 | F26: =ROUND(D26*E26,0) -> 4831400 | G26: 28 | I26: =G26*100%/D26 -> 0.16 | J26: =I26*F26 -> 773024
A27: 2.1.8 | B27: Hojalatería Zincalum liso 0.5mm - FORRO Y BAJADAS | C27: m | D27: 102.2 | E27: =+P.U!F379 -> 6368 | F27: =ROUND(D27*E27,0) -> 650810 | G27: =28+28+8+8 -> 72 | I27: =G27*100%/D27 -> 0.70450098 | J27: =I27*F27 -> 458496.28
A28: 2.1.9 | B28: Forro de Aleros y Frontones | C28: m² | D28: 230 | E28: =+P.U!F425 -> 17037 | F28: =ROUND(D28*E28,0) -> 3918510 | I28: =G28*100%/D28 -> 0 | J28: =I28*F28 -> 0
A29: 2.2 | B29: Pavimentos
A30: 2.2.1 | B30: Retiro de revestimiento de piso existente | C30: m² | D30: 1376.95 | E30: =+P.U!F469 -> 3995 | F30: =ROUND(D30*E30,0) -> 5500915 | G30: =(36.3*7)+17.5+55.3 -> 326.9 | H30: m2 | I30: =G30*100%/D30 -> 0.23740877 | J30: =I30*F30 -> 1305965.4
A31: 2.2.2 | B31: Ceramica Blanco mate 60 x 60 cm | C31: m² | D31: 162.96 | E31: =+P.U!F513 -> 25485 | F31: =ROUND(D31*E31,0) -> 4153036 | I31: =G31*100%/D31 -> 0 | J31: =I31*F31 -> 0
A32: 2.2.3 | B32: Porcelanato Artech Gris Mate Inout Antideslizante 23x120 | C32: m² | D32: 1047.99 | E32: =+P.U!F557 -> 37262 | F32: =ROUND(D32*E32,0) -> 39050203 | G32: =(36.3*3)+17.5 -> 126.4 | H32: m2 | I32: =G32*100%/D32 -> 0.12061184 | J32: =I32*F32 -> 4709916.8
A33: 2.2.4 | B33: Guardapolvo para Porcelanato Artech Gris Mate | C33: m | D33: 798.3 | E33: =+P.U!F601 -> 6867 | F33: =ROUND(D33*E33,0) -> 5481926 | G33: =24.5+24.5+24.5+12 -> 85.5 | H33: ml | I33: =G33*100%/D33 -> 0.10710259 | J33: =I33*F33 -> 587128.49
A34: 2.2.5 | B34: Piso vinilico premium excelon raffia stream with dimon 10 | C34: m | D34: 166 | E34: =+P.U!F645 -> 53974 | F34: =ROUND(D34*E34,0) -> 8959684 | I34: =G34*100%/D34 -> 0 | J34: =I34*F34 -> 0
A35: 2.2.6 | B35: Retiro de artefactos existentes | C35: un | D35: 5 | E35: =+P.U!F689 -> 7125 | F35: =ROUND(D35*E35,0) -> 35625 | I35: =G35*100%/D35 -> 0 | J35: =I35*F35 -> 0
A36: 2.2.7 | B36: Pintura Poliuretano Multicancha | C36: m² | D36: 419 | E36: =+P.U!F733 -> 20825 | F36: =ROUND(D36*E36,0) -> 8725675 | I36: =G36*100%/D36 -> 0 | J36: =I36*F36 -> 0
A37: 2.2.8 | B37: Pavimento de seguridad | C37: m² | D37: 138.8 | E37: =+P.U!F777 -> 70625 | F37: =ROUND(D37*E37,0) -> 9802750 | I37: =G37*100%/D37 -> 0 | J37: =I37*F37 -> 0
A38: 2.3 | B38: Terminaciones muros
A39: 2.3.1 | B39: Cerámica Blanco brillante | C39: m² | D39: 377.56 | E39: =+P.U!F821 -> 20560 | F39: =ROUND(D39*E39,0) -> 7762634 | I39: =G39*100%/D39 -> 0 | J39: =I39*F39 -> 0
A40: 2.3.2 | B40: Pintura Esmalte al Agua color por definir | C40: m² | D40: 2312.09 | E40: =+P.U!F865 -> 9445 | F40: =ROUND(D40*E40,0) -> 21837690 | G40: =30*3 -> 90 | H40: m2 | I40: =G40*100%/D40 -> 0.03892582 | J40: =I40*F40 -> 850050
...

Sheet avance proyectado 20%
A1: PRESUPUESTO OBRAS CIVILES
A2: Licitación: CONSERVACIÓN ESCUELA JUAN SANDOVAL CARRASCO | E2: Fecha: 17-03-2025 | G2: % Avance | H2: =J152/F152 -> 0.20395051
A3: Ubicación: SANTA ELENA N°385, COQUIMBO | E3: Versión:
A4: Ítem | B4: Descripción | C4: Unidad | D4: Cantidad | E4: P. Unitario ($) | F4: P. Total ($) | G4: Cant avance | H4: unidad | I4: avance % | J4: monto avance
A5: 0 | B5: GENERALIDADES
A6: 1 | B6: OBRAS PREVIAS
A7: 1.1 | B7: Letrero indicativo de la obra | C7: Un | D7: 1 | E7: 1450000 | F7: =D7*E7 -> 1450000 | G7: 1 | H7: unidad | I7: =G7*100%/D7 -> 1 | J7: =F7*I7 -> 1450000
A8: 1.2 | B8: Cierres Provisorios | C8: Ml | D8: 60 | E8: 38500 | F8: =D8*E8 -> 2310000 | G8: 30 | H8: m lineal | I8: =G8*100%/D8 -> 0.5 | J8: =F8*I8 -> 1155000
A9: 1.3 | B9: Intalación de faena
A10: 1.3.1 | B10: Oficina Jefatura | C10: INCLUIDO EN GASTOS GENERALES | G10: INCLUIDO EN GASTOS GENERALES
A11: 1.3.2 | B11: Bodegas | C11: INCLUIDO EN GASTOS GENERALES | G11: INCLUIDO EN GASTOS GENERALES
A12: 1.3.3 | B12: Comedor | C12: INCLUIDO EN GASTOS GENERALES | G12: INCLUIDO EN GASTOS GENERALES
A13: 1.3.4 | B13: Servicios Higienicos | C13: INCLUIDO EN GASTOS GENERALES | G13: INCLUIDO EN GASTOS GENERALES
A14: 1.3.5 | B14: Camarines | C14: INCLUIDO EN GASTOS GENERALES | G14: INCLUIDO EN GASTOS GENERALES
C15: SUBTOTAL
A16: 2 | B16: MEJORAMIENTO
A17: 2.1 | B17: Mejoramiento Complejo de Cubierta
A18: 2.1.1 | B18: Retiro de cubierta existente
A19: 2.1.1.1 | B19: Retiro de cubierta existente zinc | C19: m² | D19: 609.01 | E19: =+P.U!F28 -> 7246 | F19: =ROUND(D19*E19,0) -> 4412886 | G19: 360 | H19: m2 | I19: =G19*100%/D19 -> 0.5911233 | J19: =I19*F19 -> 2608559.7
A20: 2.1.1.2 | B20: Retiro, traslado y dispoción de cubierta de asbesto cemento | C20: m² | D20: 1271.71 | E20: =+P.U!F75 -> 24172 | F20: =ROUND(D20*E20,0) -> 30739774 | I20: =G20*100%/D20 -> 0 | J20: =I20*F20 -> 0
A21: 2.1.2 | B21: Lana de vidrio 91mm R100/213 (Para cubierta PV4) | C21: m² | D21: 1880.72 | E21: =P.U!F114 -> 3885 | F21: =ROUND(D21*E21,0) -> 7306597 | G21: 360 | I21: =G21*100%/D21 -> 0.19141605 | J21: =I21*F21 -> 1398600
A22: 2.1.3 | B22: Membrana Hidrofuga Tyvek (Para cubierta PV4) | C22: m² | D22: 1880.72 | E22: =P.U!F159 -> 2611 | F22: =ROUND(D22*E22,0) -> 4910560 | G22: 360 | I22: =G22*100%/D22 -> 0.19141605 | J22: =I22*F22 -> 939960.02
A23: 2.1.4 | B23: Placa OSB (Para cubierta PV4) | C23: m² | D23: 1880.72 | E23: =P.U!F203 -> 8920 | F23: =ROUND(D23*E23,0) -> 16776022 | G23: 360 | H23: m2 | I23: =G23*100%/D23 -> 0.19141605 | J23: =I23*F23 -> 3211199.9
A24: 2.1.5 | B24: Cubierta PV4 | C24: m² | D24: 1880.72 | E24: =P.U!F248 -> 18515 | F24: =ROUND(D24*E24,0) -> 34821531 | G24: 360 | I24: =G24*100%/D24 -> 0.19141605 | J24: =I24*F24 -> 6665400
A25: 2.1.6 | B25: Hojalatería Zincalum liso 0.5mm - CABALLETE | C25: m | D25: 244 | E25: =+P.U!F291 -> 10463 | F25: =ROUND(D25*E25,0) -> 2552972 | G25: =28+15+13 -> 56 | I25: =G25*100%/D25 -> 0.2295082 | J25: =I25*F25 -> 585928
A26: 2.1.7 | B26: Hojalatería Zincalum liso 0.5mm - CANALETA | C26: m | D26: 175 | E26: =+P.U!F335 -> 27608 | F26: =ROUND(D26*E26,0) -> 4831400 | G26: =28+28 -> 56 | I26: =G26*100%/D26 -> 0.32 | J26: =I26*F26 -> 1546048
A27: 2.1.8 | B27: Hojalatería Zincalum liso 0.5mm - FORRO Y BAJADAS | C27: m | D27: 102.2 | E27: =+P.U!F379 -> 6368 | F27: =ROUND(D27*E27,0) -> 650810 | G27: 102.2 | I27: =G27*100%/D27 -> 1 | J27: =I27*F27 -> 650810
A28: 2.1.9 | B28: Forro de Aleros y Frontones | C28: m² | D28: 230 | E28: =+P.U!F425 -> 17037 | F28: =ROUND(D28*E28,0) -> 3918510 | I28: =G28*100%/D28 -> 0 | J28: =I28*F28 -> 0
A29: 2.2 | B29: Pavimentos
A30: 2.2.1 | B30: Retiro de revestimiento de piso existente | C30: m² | D30: 1376.95 | E30: =+P.U!F469 -> 3995 | F30: =ROUND(D30*E30,0) -> 5500915 | G30: =(36.3*7)+55.5+17.5 -> 327.1 | H30: m2 | I30: =G30*100%/D30 -> 0.23755401 | J30: =I30*F30 -> 1306764.4
A31: 2.2.2 | B31: Ceramica Blanco mate 60 x 60 cm | C31: m² | D31: 162.96 | E31: =+P.U!F513 -> 25485 | F31: =ROUND(D31*E31,0) -> 4153036 | I31: =G31*100%/D31 -> 0 | J31: =I31*F31 -> 0
A32: 2.2.3 | B32: Porcelanato Artech Gris Mate Inout Antideslizante 23x120 | C32: m² | D32: 1047.99 | E32: =+P.U!F557 -> 37262 | F32: =ROUND(D32*E32,0) -> 39050203 | G32: 327.1 | H32: m2 | I32: =G32*100%/D32 -> 0.3121213 | J32: =I32*F32 -> 12188400
A33: 2.2.4 | B33: Guardapolvo para Porcelanato Artech Gris Mate | C33: m | D33: 798.3 | E33: =+P.U!F601 -> 6867 | F33: =ROUND(D33*E33,0) -> 5481926 | G33: =(24.5*8) -> 196 | H33: ml | I33: =G33*100%/D33 -> 0.24552173 | J33: =I33*F33 -> 1345932
A34: 2.2.5 | B34: Piso vinilico premium excelon raffia stream with dimon 10 | C34: m | D34: 166 | E34: =+P.U!F645 -> 53974 | F34: =ROUND(D34*E34,0) -> 8959684 | G34: 166 | I34: =G34*100%/D34 -> 1 | J34: =I34*F34 -> 8959684
A35: 2.2.6 | B35: Retiro de artefactos existentes | C35: un | D35: 5 | E35: =+P.U!F689 -> 7125 | F35: =ROUND(D35*E35,0) -> 35625 | I35: =G35*100%/D35 -> 0 | J35: =I35*F35 -> 0
A36: 2.2.7 | B36: Pintura Poliuretano Multicancha | C36: m² | D36: 419 | E36: =+P.U!F733 -> 20825 | F36: =ROUND(D36*E36,0) -> 8725675 | I36: =G36*100%/D36 -> 0 | J36: =I36*F36 -> 0
A37: 2.2.8 | B37: Pavimento de seguridad | C37: m² | D37: 138.8 | E37: =+P.U!F777 -> 70625 | F37: =ROUND(D37*E37,0) -> 9802750 | I37: =G37*100%/D37 -> 0 | J37: =I37*F37 -> 0
A38: 2.3 | B38: Terminaciones muros
A39: 2.3.1 | B39: Cerámica Blanco brillante | C39: m² | D39: 377.56 | E39: =+P.U!F821 -> 20560 | F39: =ROUND(D39*E39,0) -> 7762634 | I39: =G39*100%/D39 -> 0 | J39: =I39*F39 -> 0
A40: 2.3.2 | B40: Pintura Esmalte al Agua color por definir | C40: m² | D40: 2312.09 | E40: =+P.U!F865 -> 9445 | F40: =ROUND(D40*E40,0) -> 21837690 | G40: 1205.72 | H40: m2 | I40: =G40*100%/D40 -> 0.52148489 | J40: =I40*F40 -> 11388025
...

Sheet P.U
A1: Rendimiento (Un/jornada): | B1: 56 | C1: (edita este valor) | E1: Parámetros (editar):
A2: Unidad de pago: | B2: m² | E2: Gastos Generales | F2: 0.15
E3: Utilidad | F3: 0.2
B4: 2.1.1.1 Retiro cubierta existen | E4: iva | F4: 0.19
A5: MATERIALES
A6: # | B6: Descripción / Material | C6: Unidad | D6: Cantidad | E6: $ Unitario | F6: Subtotal
A7: 1 | B7: Film Polietileno 200 mic (protección) | C7: m² | D7: =ROUND(1/$B$1,2) -> 0.02 | E7: 388 | F7: =ROUND(IFERROR(D7*E7,0),0) -> 8
A8: 2 | B8: Sacos polipropileno 50 kg | C8: un | D8: =ROUND(1/$B$1,2) -> 0.02 | E8: 4613 | F8: =ROUND(IFERROR(D8*E8,0),0) -> 92
A9: 3 | B9: Consumibles (cintas/discos) | C9: gl | D9: =ROUND(1/$B$1,2) -> 0.02 | E9: 4832 | F9: =ROUND(IFERROR(D9*E9,0),0) -> 97
E10: TOTAL | F10: =ROUND(SUM(F6:F9),0) -> 197
A12: MANO DE OBRA (Rendimiento por jornada)
A13: # | B13: Descripción / Material | C13: Unidad | D13: Cantidad | E13: $ Unitario | F13: Subtotal
A14: 1 | B14: Maestro techumbre | C14: día | D14: 0.03 | E14: 65000 | F14: =ROUND(IFERROR(D14*E14,0),0) -> 1950
A15: 2 | B15: Ayudante | C15: día | D15: 0.03 | E15: 50000 | F15: =ROUND(IFERROR(D15*E15,0),0) -> 1500
E16: TOTAL | F16: =SUM(F14:F15) -> 3450
E17: Leyes sociales 50% | F17: =F16*0.5 -> 1725
E18: TOTAL MO | F18: =F16+F17 -> 5175
A20: MAQUINARIA Y HERRAMIENTAS (prorrateo por unidad)
A21: # | B21: Descripción / Material | C21: Unidad | D21: Cantidad | E21: $ Unitario | F21: Subtotal
A22: 1 | B22: Andamio (prorrateo) | C22: día | D22: 0.03 | E22: 7000 | F22: =ROUND(IFERROR(D22*E22,0),0) -> 210
A23: 2 | B23: Camión 3/4 (apoyo) | C23: día | D23: 0.03 | E23: 55454 | F23: =ROUND(IFERROR(D23*E23,0),0) -> 1664
E24: TOTAL | F24: =SUM(F22:F23) -> 1874
A26: RESUMEN
B27: Descripción / Material | C27: Unidad | D27: Cantidad | E27: $ Unitario | F27: Subtotal
E28: Costo Directo | F28: =F10+F18+F24 -> 7246
E29: Gastos Generales | F29: =ROUND(F28*F2,0) -> 1087
E30: Utilidad | F30: =ROUND(F28*F3,0) -> 1449
E31: Sub-Total Neto | F31: =F28+F29+F30 -> 9782
E32: IVA 19% | F32: =ROUND(F30*0.19,0) -> 275
D33: (m²) | E33: PRECIO UNITARIO | F33: =F31+F32 -> 10057
A45: Rendimiento (Un/jornada): | B45: 40 | C45: (edita este valor) | E45: Parámetros (editar):
A46: Unidad de pago: | B46: m² | E46: Gastos Generales | F46: 0.15
E47: Utilidad | F47: 0.2
B48: 2.1.1.2 Retiro, traslado y disp | E48: Utilidad | F48: 0.19
A49: MATERIALES
A50: # | B50: Descripción / Material | C50: Unidad | D50: Cantidad | E50: $ Unitario | F50: Subtotal
A51: 1 | B51: Polietileno 200 mic (encapsulado) | C51: m² | D51: 0.3 | E51: 388 | F51: =ROUND(IFERROR(D51*E51,0),0) -> 116
A52: 2 | B52: Bolsas residuo peligroso rotuladas | C52: un | D52: 0.25 | E52: 4613 | F52: =ROUND(IFERROR(D52*E52,0),0) -> 1153
A53: 3 | B53: Sellante PU (sellos/bolsas) | C53: cart | D53: 0.04 | E53: 4832 | F53: =ROUND(IFERROR(D53*E53,0),0) -> 193
A54: 4 | B54: Buzos desechables tipo Tyvek 4520 | C54: un | D54: 0.4 | E54: 1891 | F54: =ROUND(IFERROR(D54*E54,0),0) -> 756
...

Sheet Anexo 4
A1: Anexo N°4
A3: ANÁLISIS DE PRECIOS UNITARIOS
A5: NOMBRE DE LA OBRA: SERVICIO DE OBRAS DE CONSERVACIÓN EN ESCUELA JUAN SANDOVAL CARRASCO DEL SERVICIO LOCAL DE EDUCACIÓN PÚBLICA PUERTO CORDILLERA.
A6: ID
A7: CONTRATISTA: CONSTRUCTORA RCR SPA
A9: PARTIDA | B9: =+P.U!B224 -> Cubierta PV4 | C9: ITEM : | D9: UNIDAD | F9: PRECIO
C10: =+P.U!A224 -> 2.1.5 | D10: =+P.U!B222 -> m² | F10: UNITARIO
A11: NOMBRE | F11: =+P.U!F248 -> 18515
A13: MATERIALES (A)
A14: Nº | B14: ITEM | C14: UNIDAD | D14: CANTIDAD | E14: PRECIO | F14: VALOR
E15: UNITARIO | F15: TOTAL
A16: =+P.U!A227 -> 1 | B16: =+P.U!B227 -> Plancha PV4 0,5 mm c/ anticondensante | C16: =+P.U!C227 -> m² | D16: =+P.U!D227 -> 1.05 | E16: =+P.U!E227 -> 10250 | F16: =+P.U!F227 -> 10763
A17: =+P.U!A228 -> 2 | B17: =+P.U!B228 -> Tornillo c/ arandela neopreno | C17: =+P.U!C228 -> un | D17: =+P.U!D228 -> 8 | E17: =+P.U!E228 -> 80 | F17: =+P.U!F228 -> 640
A18: =+P.U!A229 -> 3 | B18: =+P.U!B229 -> Sellante PU remates | C18: =+P.U!C229 -> cart | D18: =+P.U!D229 -> 0.02 | E18: =+P.U!E229 -> 4832 | F18: =+P.U!F229 -> 97
E21: TOTAL | F21: =+P.U!F230 -> 11500
A24: MANO DE OBRA (B)
A25: Nº | B25: ITEM | C25: UNIDAD | D25: CANTIDAD | E25: PRECIO | F25: VALOR
E26: UNITARIO | F26: TOTAL
A27: =+P.U!A234 -> 1 | B27: =+P.U!B234 -> Techador | C27: =+P.U!C234 -> día | D27: =+P.U!D234 -> 0.04 | E27: =+P.U!E234 -> 65000 | F27: =+P.U!F234 -> 2600
A28: =+P.U!A235 -> 2 | B28: =+P.U!B235 -> Ayudante | C28: =+P.U!C235 -> día | D28: =+P.U!D235 -> 0.04 | E28: =+P.U!E235 -> 50000 | F28: =+P.U!F235 -> 2000
E31: SUBTOTAL M.O | F31: =+P.U!F236 -> 4600
B32: LEYES SOCIALES | C32: % | D32: =+P.U!F237 -> 2300
E33: TOTAL MO | F33: =+P.U!F238 -> 6900
A36: EQUIPOS Y HERRAMIENTAS (C)
A37: Nº | B37: ITEM | C37: UNIDAD | D37: CANTIDAD | E37: PRECIO | F37: VALOR
E38: UNITARIO | F38: TOTAL
A39: =+P.U!A242 -> 1 | B39: =+P.U!B242 -> Atornillador | C39: =+P.U!C242 -> día | D39: =+P.U!D242 -> 0.01 | E39: =+P.U!E242 -> 8000 | F39: =+P.U!F242 -> 80
A40: =+P.U!A243 -> 2 | B40: =+P.U!B243 -> Andamio (apoyo) | C40: =+P.U!C243 -> día | D40: =+P.U!D243 -> 0.01 | E40: =+P.U!E243 -> 3500 | F40: =+P.U!F243 -> 35
E43: TOTAL | F43: =+P.U!F244 -> 115
B47: ____________________________________
B48: ROGER CARMONA / 12,441,221-8
B49: REPRESENTANTE LEGAL
B50: CONSTRUCTORA RCR SPA
A53: Anexo N°4
A55: ANÁLISIS DE PRECIOS UNITARIOS
A57: NOMBRE DE LA OBRA: SERVICIO DE OBRAS DE CONSERVACIÓN EN ESCUELA JUAN SANDOVAL CARRASCO DEL SERVICIO LOCAL DE EDUCACIÓN PÚBLICA PUERTO CORDILLERA.
A58: ID
A59: CONTRATISTA: CONSTRUCTORA RCR SPA
A61: PARTIDA | B61: Porcel. Artech gris mate inout antides 23x120 | C61: ITEM : | D61: UNIDAD | F61: PRECIO
C62: =+P.U!A532 -> 2.2.3 | D62: =+P.U!B530 -> m² | F62: UNITARIO
...
